<?xml version="1.0"?>
<robot xmlns:xacro="http://www.ros.org/wiki/xacro" name="rover">
<xacro:include filename="$(find my_robot)/urdf/robot.gazebo" />

<xacro:property name="c1"       value="0.083"/>
<xacro:property name="c2"       value="0.5"/>
<xacro:property name="mass"     value="1"/>
<xacro:property name="width"    value="0.8"/>
<xacro:property name="height"   value="0.1"/>
<xacro:property name="depth"    value="0.7 "/>
<xacro:property name="radius"   value="0.15 "/>


<!--  	#############	BODY		############		 -->


<!-- BASE LINK AND JOINT -->

  <link name="base_footprint"/> 

  <link name="base_link">   
    <visual>
      <origin xyz="0 0 0" rpy="0.0 0.0 0.0"/>
      <geometry>
        <box size="0.8 0.7 0.1" />
      </geometry>
      <material name="DarkGrey">
        <color rgba="0.25 0.25 0.25 1.0"/>
      </material>
    </visual>
    <collision>
      <origin xyz="0 0 0" rpy="0.0 0.0 0.0"/>
      <geometry>
        <box size="0.8 0.7 0.1" />
      </geometry>
    </collision>   
    <inertial>
      <mass value="0.5"/>
      <origin xyz="0.0 0.0 0" rpy="0.0 0.0 0.0"/>
      <inertia  ixx="${c1 * mass * (height * height + depth * depth)}" ixy="0.0" ixz="0.0" 
                iyy="${c1 * mass * (height * height + depth * depth)}" iyz="0.0" 
                izz="${c1 * mass * (height * height + depth * depth)}"/>
    </inertial>
  </link>

<joint name="base_joint" type="fixed">
		<origin xyz="0 0 0.135" rpy="0 0 0" />
		<parent link="base_footprint"/>
		<child link="base_link" />
	</joint>


<!--WHEEL LINKS AND JOINT -->

<xacro:macro name="wheel" params="name x y">
    <link name="wheel_${name}_link">       
        <inertial>
            <origin xyz="0 0 0" rpy="0 0 0"/>
            <mass value="0.25"/>
            <inertia  ixx="${c2 * mass * (radius*radius)}" ixy="0.0" ixz="0.0" 
                      iyy="${c2 * mass * (radius*radius)}" iyz="0.0" 
                      izz="${c2 * mass * (radius*radius)}"/>
        </inertial>
        <visual name="wheel_${name}_visual">
            <origin xyz="0 0 0" rpy="1.57 0.0 0.0"/>
            <geometry>
              <cylinder radius="0.15" length="0.1"/>            
            </geometry>
            <material name="LightGrey">
              <color rgba="0.7 0.7 0.7 1.0"/>
            </material>
        </visual>       
        <collision>
            <origin xyz="0 0 0" rpy="1.57 0.0 0.0"/>
            <geometry>
              <cylinder radius="0.15" length="0.1"/>            
            </geometry>
        </collision>
    </link>
    <joint name="wheel_${name}_joint" type="continuous">
        <origin xyz="${x} ${y} 0" rpy="0 0 0"/>
        <parent link="base_link"/>
        <child link="wheel_${name}_link"/>
        <axis xyz="0 1 0"/>
        <limit velocity="100.0" effort="1000.0" />
        <dynamics damping="1.0" friction="1.0"/>
    </joint>
</xacro:macro>

<!-- Wheel Creating using macros -->
<xacro:wheel name="rear_right"  x="0.250" y =" 0.40"/>
<xacro:wheel name="front_right" x="-0.250" y =" 0.40"/>
<xacro:wheel name="front_left"  x="-0.250" y =" -0.40"/>
<xacro:wheel name="rear_left"   x="0.250" y =" -0.40"/>




<!--  	#############	SENSORS		############		 -->


     <!-- HOKUYO LASER	 -->

  <link name="hokuyo_link">
    <collision>
      <origin xyz="0 0 0 " rpy="0 0 0"/>
      <geometry>
         <box size="0.05 0.05 0.05"/>
      </geometry>
    </collision>
    <visual>
      <origin xyz="0 0 0" rpy="0 0 0"/>
      <geometry>
	    <box size="0.05 0.05 0.05"/>
      </geometry>
    </visual>
    <inertial>
      <mass value="1e-5" />
      <origin xyz="0 0 0.15" rpy="0 0 0"/>
      <inertia ixx="1e-6" ixy="0" ixz="0" iyy="1e-6" iyz="0" izz="1e-6" />
    </inertial>
  </link>

  	<joint name="hokuyo_joint" type="fixed">
    <axis xyz="0 1 0" />
    <origin xyz="0 0 0.325" rpy="0 0 0"/>
    <parent link="base_footprint"/>
    <child link="hokuyo_link"/>
    </joint>


 <!-- CAMERA -->

	 <link name="camera_link_top">
		<collision name="camera_top_collision">
			<origin xyz="0 0 0 " rpy="0 0 0"/>
			<geometry>
		<box size="0.04 0.024 0.003"/>
			</geometry>
		</collision>
		<visual name='camera_top_visual'>
			<origin xyz="0 0 0 " rpy="0 0 0"/>
			<geometry>
		<box size="0.04 0.024 0.003"/>
			</geometry>
		</visual>
		<inertial>
			<mass value="1e-5" />
			<origin xyz="0.4 0 0.15" rpy="0 0 0"/>
			<inertia ixx="1e-6" ixy="0" ixz="0" iyy="1e-6" iyz="0" izz="1e-6" />
		</inertial>
	</link>
  
 	<joint type="fixed" name="camera_joint_top">
		<axis xyz="0 1 0" />
		<origin xyz="0.4 0 0.15" rpy="0 0 0"/>
		<parent link="base_footprint"/>
		<child link="camera_link_top"/>
	</joint>

   <!-- IMU -->

	 <link name="imu_link">
		<collision name="imu_link_collision">
			<origin xyz="0 0 0 " rpy="0 0 0"/>
			<geometry>
		<box size="0.05 0.003 0.025"/>
			</geometry>
		</collision>
		<visual name='imu_link_visual'>
			<origin xyz="0 0 0 " rpy="0 0 0"/>
			<geometry>
		<box size="0.05 0.003 0.025"/>
			</geometry>
		</visual>
		<inertial>
			<mass value="1e-5" />
			<origin xyz="0 0 0.15" rpy="0 0 0"/>
			<inertia ixx="1e-6" ixy="0" ixz="0" iyy="1e-6" iyz="0" izz="1e-6" />
		</inertial>
	</link>
  
 	<joint type="fixed" name="imu_joint">
		<axis xyz="0 1 0" />
		<origin xyz="0 0 0.15" rpy="0 0 0"/>
		<parent link="base_footprint"/>
		<child link="imu_link"/>
	</joint>


</robot>